<?xml version="1.0" encoding="utf-8"?>
<robot name="ModularBot">
  <!-- <xacro:include filename="$(find modular)/urdf/config.xacro" />
    <xacro:include filename="$(find modular)/urdf/modular.gazebo" /> -->
  <!-- 
    <xacro:property name="size1" value="0.05" />
    <xacro:property name="size2" value="0.055" />
    <xacro:property name="size3" value="0.06" /> -->
  <!-- <xacro:property name="pi" value="3.1415" /> -->
  <material name="blue">
    <color rgba="0 0 0.8 1"/>
  </material>
  <material name="black">
    <color rgba="0 0 0 1"/>
  </material>
  <material name="white">
    <color rgba="1 1 1 1"/>
  </material>
  <material name="grey">
    <color rgba="0.5 0.5 0.5 1"/>
  </material>
  <material name="red">
    <color rgba="1 0 0 1"/>
  </material>
  <material name="green">
    <color rgba="0 1 0 1"/>
  </material>
  <material name="yellow">
    <color rgba="1 1 0 1"/>
  </material>
  <material name="tree_green">
    <color rgba="0.13 0.54 0.13 1"/>
  </material>
  <link name="world"/>
  <joint name="reference" type="floating">
    <parent link="world"/>
    <child link="base_link"/>
  </joint>
  <origin rpy="0 0 0" xyz="0.0 0.0 0.8"/>
  <link name="base_link">
    <inertial>
      <mass value="0.001"/>
      <inertia ixx="1.0e-06" ixy="0.0" ixz="0.0" iyy="1.0e-06" iyz="0.0" izz="1.0e-06"/>
    </inertial>
  </link>
  <gazebo>
    <plugin filename="libxbot2_gz_joint_server.so" name="xbot2_gz_joint_server">
      <pid>
        <gain d="10" name="small_mot" p="100"/>
        <gain d="50" name="medium_mot" p="500"/>
        <gain d="100" name="big_mot" p="1000"/>
        <gain name="J1_A" profile="medium_mot"/>
        <gain d="50" name="J_wheel_A" p="0"/>
        <gain name="J1_B" profile="medium_mot"/>
        <gain d="50" name="J_wheel_B" p="0"/>
        <gain name="J1_C" profile="medium_mot"/>
        <gain d="50" name="J_wheel_C" p="0"/>
        <gain name="J1_D" profile="medium_mot"/>
        <gain d="50" name="J_wheel_D" p="0"/>
      </pid>
    </plugin>
  </gazebo>
  <joint name="fixed" type="fixed">
    <parent link="base_link"/>
    <child link="mobile_base"/>
    <axis rpy="0 0 0" xyz="0 0 1"/>
    <origin rpy="0.0 0.0 0.0" xyz="0.0 0.0 0.0"/>
  </joint>
  <link name="mobile_base">
    <visual>
      <origin rpy="0.0 -0.0 0.0" xyz="0 0 0"/>
      <geometry>
        <mesh filename="package://concert_resources/models/modular/meshes/concert/concert_central_body.stl" scale="0.001 0.001 0.001"/>
      </geometry>
      <material name="grey"/>
    </visual>
    <collision>
      <origin rpy="0.0 -0.0 0.0" xyz="0 0 0"/>
      <geometry>
        <mesh filename="package://concert_resources/models/modular/meshes/concert/simple/concert_central_body.stl" scale="0.001 0.001 0.001"/>
      </geometry>
    </collision>
    <inertial>
      <origin rpy="0 0 0" xyz="0.012213513 0.0 -0.21761073"/>
      <mass value="127.57599"/>
      <inertia ixx="19.025397" ixy="-0.62823044" ixz="-0.064261485" iyy="13.251602" iyz="0.91864796" izz="23.575473"/>
    </inertial>
  </link>
  <!-- camera body, with origin at bottom screw mount -->
  <joint name="D435i_camera_front_joint" type="fixed">
    <origin rpy="0 0.261799 0" xyz="0.402872 0.0 -0.078218"/>
    <parent link="mobile_base"/>
    <child link="D435i_camera_front_bottom_screw_frame"/>
  </joint>
  <link name="D435i_camera_front_bottom_screw_frame"/>
  <!-- camera body, with origin at bottom screw mount -->
  <joint name="D435i_camera_back_joint" type="fixed">
    <origin rpy="0 0.261799 3.141593" xyz="-0.402872 0.0 -0.078218"/>
    <parent link="mobile_base"/>
    <child link="D435i_camera_back_bottom_screw_frame"/>
  </joint>
  <link name="D435i_camera_back_bottom_screw_frame"/>
  <!-- camera body, with origin at bottom screw mount -->
  <joint name="T265_camera_left_joint" type="fixed">
    <origin rpy="3.141593 0.0 1.570796" xyz="0.02375 0.37245 -0.062"/>
    <parent link="mobile_base"/>
    <child link="T265_camera_left_pose_frame"/>
  </joint>
  <link name="T265_camera_left_pose_frame"/>
  <!-- camera body, with origin at bottom screw mount -->
  <joint name="T265_camera_right_joint" type="fixed">
    <origin rpy="0 0.0 -1.570796" xyz="0.02375 -0.37245 -0.062"/>
    <parent link="mobile_base"/>
    <child link="T265_camera_right_pose_frame"/>
  </joint>
  <link name="T265_camera_right_pose_frame"/>
  <!-- camera body, with origin at bottom screw mount -->
  <joint name="velodyne_front_base_mount_joint" type="fixed">
    <origin rpy="0.0 0.0 0.0" xyz="0.5305 0.315 -0.1"/>
    <parent link="mobile_base"/>
    <child link="velodyne_front_base_link"/>
  </joint>
  <link name="velodyne_front_base_link"/>
  <!-- camera body, with origin at bottom screw mount -->
  <joint name="velodyne_back_base_mount_joint" type="fixed">
    <origin rpy="0.0 0.0 3.141593" xyz="-0.5305 -0.315 -0.1"/>
    <parent link="mobile_base"/>
    <child link="velodyne_back_base_link"/>
  </joint>
  <link name="velodyne_back_base_link"/>
  <!-- Add front-left Bosch USS5 -->
  <joint name="bosch_uss5_front_left_joint" type="fixed">
    <origin rpy="0.0 1.963496 0.0" xyz="0.5105 0.315 -0.129"/>
    <parent link="mobile_base"/>
    <child link="bosch_uss5_front_left"/>
  </joint>
  <link name="bosch_uss5_front_left"/>
  <!-- Add front-right Bosch USS5 -->
  <joint name="bosch_uss5_front_right_joint" type="fixed">
    <origin rpy="0.0 1.963496 0.0" xyz="0.5105 -0.315 -0.129"/>
    <parent link="mobile_base"/>
    <child link="bosch_uss5_front_right"/>
  </joint>
  <link name="bosch_uss5_front_right"/>
  <!-- Add back-left Bosch USS5 -->
  <joint name="bosch_uss5_back_left_joint" type="fixed">
    <origin rpy="0.0 1.963496 3.141593" xyz="-0.5105 0.315 -0.129"/>
    <parent link="mobile_base"/>
    <child link="bosch_uss5_back_left"/>
  </joint>
  <link name="bosch_uss5_back_left"/>
  <!-- Add back-right Bosch USS5 -->
  <joint name="bosch_uss5_back_right_joint" type="fixed">
    <origin rpy="0.0 1.963496 3.141593" xyz="-0.5105 -0.315 -0.129"/>
    <parent link="mobile_base"/>
    <child link="bosch_uss5_back_right"/>
  </joint>
  <link name="bosch_uss5_back_right"/>
  <!-- Add left-front Bosch USS5 -->
  <joint name="bosch_uss5_left_front_joint" type="fixed">
    <origin rpy="0.0 1.963496 1.570796" xyz="0.4515 0.365 -0.117"/>
    <parent link="mobile_base"/>
    <child link="bosch_uss5_left_front"/>
  </joint>
  <link name="bosch_uss5_left_front"/>
  <!-- Add left-back Bosch USS5 -->
  <joint name="bosch_uss5_left_back_joint" type="fixed">
    <origin rpy="0.0 1.963496 1.570796" xyz="-0.4515 0.365 -0.117"/>
    <parent link="mobile_base"/>
    <child link="bosch_uss5_left_back"/>
  </joint>
  <link name="bosch_uss5_left_back"/>
  <!-- Add right-front Bosch USS5 -->
  <joint name="bosch_uss5_right_front_joint" type="fixed">
    <origin rpy="0.0 1.963496 -1.570796" xyz="0.4515 -0.365 -0.117"/>
    <parent link="mobile_base"/>
    <child link="bosch_uss5_right_front"/>
  </joint>
  <link name="bosch_uss5_right_front"/>
  <!-- Add right-back Bosch USS5 -->
  <joint name="bosch_uss5_right_back_joint" type="fixed">
    <origin rpy="0.0 1.963496 -1.570796" xyz="-0.4515 -0.365 -0.117"/>
    <parent link="mobile_base"/>
    <child link="bosch_uss5_right_back"/>
  </joint>
  <link name="bosch_uss5_right_back"/>
  <joint name="fixed_J1_A" type="fixed">
    <axis rpy="0 0 0" xyz="0 0 1"/>
    <parent link="mobile_base"/>
    <child link="J1_A_stator"/>
    <origin rpy="-3.141592653589793 -1.5707963267948966 0.0" xyz="0.37925 0.3125 -0.195"/>
  </joint>
  <link name="J1_A_stator">
    <visual>
      <origin rpy="0.0 -0.0 0.0" xyz="0 0 0"/>
      <geometry>
        <mesh filename="package://concert_resources/models/modular/meshes/concert/concert_steering_connection_module.stl" scale="0.001 0.001 0.001"/>
      </geometry>
      <material name="blue"/>
    </visual>
    <collision>
      <origin rpy="0.0 -0.0 0.0" xyz="0 0 0"/>
      <geometry>
        <mesh filename="package://concert_resources/models/modular/meshes/concert/simple/concert_steering_connection_module.stl" scale="0.001 0.001 0.001"/>
      </geometry>
    </collision>
    <inertial>
      <origin rpy="0 0 0" xyz="-0.0079406061 0.0 0.037039629"/>
      <mass value="1.1813661"/>
      <inertia ixx="0.0026106263" ixy="0.0" ixz="0.00017928188" iyy="0.0027438806" iyz="0.0" izz="0.0025223123"/>
    </inertial>
  </link>
  <joint name="J1_A" type="revolute">
    <axis rpy="0 0 0" xyz="0 0 1"/>
    <parent link="J1_A_stator"/>
    <child link="L_1_A"/>
    <origin rpy="-1.5707963267948966 -0.0 1.5707963267948966" xyz="-0.022 0.0 0.06075"/>
    <limit effort="127.0" lower="-2.6" upper="2.6" velocity="8.1"/>
  </joint>
  <link name="L_1_A">
    <visual>
      <origin rpy="3.141592653589793 -0.0 0.0" xyz="0 0 0"/>
      <geometry>
        <mesh filename="package://concert_resources/models/modular/meshes/concert/concert_steering_module_frame.stl" scale="0.001 0.001 0.001"/>
      </geometry>
      <material name="blue"/>
    </visual>
    <collision>
      <origin rpy="3.141592653589793 -0.0 0.0" xyz="0 0 0"/>
      <geometry>
        <mesh filename="package://concert_resources/models/modular/meshes/concert/simple/concert_steering_module_frame.stl" scale="0.001 0.001 0.001"/>
      </geometry>
    </collision>
    <inertial>
      <origin rpy="0 0 0" xyz="0.090718433 0.0 -0.22670598"/>
      <mass value="7.6995028"/>
      <inertia ixx="0.44048889" ixy="-0.03668535" ixz="0.025595962" iyy="0.52073797" iyz="-0.0026667139" izz="0.69985532"/>
    </inertial>
  </link>
  <joint name="fixed_J_wheel_A" type="fixed">
    <axis rpy="0 0 0" xyz="0 0 1"/>
    <parent link="L_1_A"/>
    <child link="J_wheel_A_stator"/>
    <origin rpy="-3.141592653589793 1.5707963267948966 0.0" xyz="0.0 0.0 0.37015"/>
  </joint>
  <link name="J_wheel_A_stator">
    <inertial>
      <mass value="0.001"/>
      <inertia ixx="1.0e-06" ixy="0.0" ixz="0.0" iyy="1.0e-06" iyz="0.0" izz="1.0e-06"/>
    </inertial>
  </link>
  <joint name="J_wheel_A" type="revolute">
    <axis rpy="0 0 0" xyz="0 0 1"/>
    <parent link="J_wheel_A_stator"/>
    <child link="wheel_A"/>
    <origin rpy="0.0 -0.0 0.0" xyz="0.0 0.0 0.0"/>
    <limit effort="24.0" lower="-10000000000.0" upper="10000000000.0" velocity="9.5"/>
  </joint>
  <link name="wheel_A">
    <visual>
      <origin rpy="0.0 -0.0 0.0" xyz="0 0 0"/>
      <geometry>
        <mesh filename="package://concert_resources/models/modular/meshes/concert/concert_wheel.stl" scale="0.001 0.001 0.001"/>
      </geometry>
      <material name="black"/>
    </visual>
    <collision>
      <origin rpy="0.0 -0.0 0.0" xyz="0 0 0"/>
      <geometry>
        <cylinder length="0.1" radius="0.16"/>
      </geometry>
    </collision>
    <inertial>
      <origin rpy="0 0 0" xyz="0.0 0.0 -0.005"/>
      <mass value="4.0116207"/>
      <inertia ixx="0.028580559" ixy="0.0" ixz="0.0" iyy="0.028580559" iyz="0.0" izz="0.044954065"/>
    </inertial>
  </link>
  <joint name="fixed_J1_B" type="fixed">
    <axis rpy="0 0 0" xyz="0 0 1"/>
    <parent link="mobile_base"/>
    <child link="J1_B_stator"/>
    <origin rpy="-3.141592653589793 -1.5707963267948966 0.0" xyz="0.37925 -0.3125 -0.195"/>
  </joint>
  <link name="J1_B_stator">
    <visual>
      <origin rpy="0.0 -0.0 0.0" xyz="0 0 0"/>
      <geometry>
        <mesh filename="package://concert_resources/models/modular/meshes/concert/concert_steering_connection_module.stl" scale="0.001 0.001 0.001"/>
      </geometry>
      <material name="blue"/>
    </visual>
    <collision>
      <origin rpy="0.0 -0.0 0.0" xyz="0 0 0"/>
      <geometry>
        <mesh filename="package://concert_resources/models/modular/meshes/concert/simple/concert_steering_connection_module.stl" scale="0.001 0.001 0.001"/>
      </geometry>
    </collision>
    <inertial>
      <origin rpy="0 0 0" xyz="-0.0079406061 0.0 0.037039629"/>
      <mass value="1.1813661"/>
      <inertia ixx="0.0026106263" ixy="0.0" ixz="0.00017928188" iyy="0.0027438806" iyz="0.0" izz="0.0025223123"/>
    </inertial>
  </link>
  <joint name="J1_B" type="revolute">
    <axis rpy="0 0 0" xyz="0 0 1"/>
    <parent link="J1_B_stator"/>
    <child link="L_1_B"/>
    <origin rpy="1.5707963267948966 -0.0 -1.5707963267948966" xyz="-0.022 0.0 0.06075"/>
    <limit effort="127.0" lower="-2.6" upper="2.6" velocity="8.1"/>
  </joint>
  <link name="L_1_B">
    <visual>
      <origin rpy="3.141592653589793 -0.0 0.0" xyz="0 0 0"/>
      <geometry>
        <mesh filename="package://concert_resources/models/modular/meshes/concert/concert_steering_module_frame.stl" scale="0.001 0.001 0.001"/>
      </geometry>
      <material name="blue"/>
    </visual>
    <collision>
      <origin rpy="3.141592653589793 -0.0 0.0" xyz="0 0 0"/>
      <geometry>
        <mesh filename="package://concert_resources/models/modular/meshes/concert/simple/concert_steering_module_frame.stl" scale="0.001 0.001 0.001"/>
      </geometry>
    </collision>
    <inertial>
      <origin rpy="0 0 0" xyz="0.090718433 0.0 -0.22670598"/>
      <mass value="7.6995028"/>
      <inertia ixx="0.44048889" ixy="-0.03668535" ixz="0.025595962" iyy="0.52073797" iyz="-0.0026667139" izz="0.69985532"/>
    </inertial>
  </link>
  <joint name="fixed_J_wheel_B" type="fixed">
    <axis rpy="0 0 0" xyz="0 0 1"/>
    <parent link="L_1_B"/>
    <child link="J_wheel_B_stator"/>
    <origin rpy="-3.141592653589793 1.5707963267948966 0.0" xyz="0.0 0.0 0.37015"/>
  </joint>
  <link name="J_wheel_B_stator">
    <inertial>
      <mass value="0.001"/>
      <inertia ixx="1.0e-06" ixy="0.0" ixz="0.0" iyy="1.0e-06" iyz="0.0" izz="1.0e-06"/>
    </inertial>
  </link>
  <joint name="J_wheel_B" type="revolute">
    <axis rpy="0 0 0" xyz="0 0 1"/>
    <parent link="J_wheel_B_stator"/>
    <child link="wheel_B"/>
    <origin rpy="0.0 -0.0 0.0" xyz="0.0 0.0 0.0"/>
    <limit effort="24.0" lower="-10000000000.0" upper="10000000000.0" velocity="9.5"/>
  </joint>
  <link name="wheel_B">
    <visual>
      <origin rpy="0.0 -0.0 0.0" xyz="0 0 0"/>
      <geometry>
        <mesh filename="package://concert_resources/models/modular/meshes/concert/concert_wheel.stl" scale="0.001 0.001 0.001"/>
      </geometry>
      <material name="black"/>
    </visual>
    <collision>
      <origin rpy="0.0 -0.0 0.0" xyz="0 0 0"/>
      <geometry>
        <cylinder length="0.1" radius="0.16"/>
      </geometry>
    </collision>
    <inertial>
      <origin rpy="0 0 0" xyz="0.0 0.0 -0.005"/>
      <mass value="4.0116207"/>
      <inertia ixx="0.028580559" ixy="0.0" ixz="0.0" iyy="0.028580559" iyz="0.0" izz="0.044954065"/>
    </inertial>
  </link>
  <joint name="fixed_J1_C" type="fixed">
    <axis rpy="0 0 0" xyz="0 0 1"/>
    <parent link="mobile_base"/>
    <child link="J1_C_stator"/>
    <origin rpy="-0.0 -1.5707963267948966 0.0" xyz="-0.37925 0.3125 -0.195"/>
  </joint>
  <link name="J1_C_stator">
    <visual>
      <origin rpy="0.0 -0.0 0.0" xyz="0 0 0"/>
      <geometry>
        <mesh filename="package://concert_resources/models/modular/meshes/concert/concert_steering_connection_module.stl" scale="0.001 0.001 0.001"/>
      </geometry>
      <material name="blue"/>
    </visual>
    <collision>
      <origin rpy="0.0 -0.0 0.0" xyz="0 0 0"/>
      <geometry>
        <mesh filename="package://concert_resources/models/modular/meshes/concert/simple/concert_steering_connection_module.stl" scale="0.001 0.001 0.001"/>
      </geometry>
    </collision>
    <inertial>
      <origin rpy="0 0 0" xyz="-0.0079406061 0.0 0.037039629"/>
      <mass value="1.1813661"/>
      <inertia ixx="0.0026106263" ixy="0.0" ixz="0.00017928188" iyy="0.0027438806" iyz="0.0" izz="0.0025223123"/>
    </inertial>
  </link>
  <joint name="J1_C" type="revolute">
    <axis rpy="0 0 0" xyz="0 0 1"/>
    <parent link="J1_C_stator"/>
    <child link="L_1_C"/>
    <origin rpy="1.5707963267948966 -0.0 -1.5707963267948966" xyz="-0.022 0.0 0.06075"/>
    <limit effort="127.0" lower="-2.6" upper="2.6" velocity="8.1"/>
  </joint>
  <link name="L_1_C">
    <visual>
      <origin rpy="3.141592653589793 -0.0 0.0" xyz="0 0 0"/>
      <geometry>
        <mesh filename="package://concert_resources/models/modular/meshes/concert/concert_steering_module_frame.stl" scale="0.001 0.001 0.001"/>
      </geometry>
      <material name="blue"/>
    </visual>
    <collision>
      <origin rpy="3.141592653589793 -0.0 0.0" xyz="0 0 0"/>
      <geometry>
        <mesh filename="package://concert_resources/models/modular/meshes/concert/simple/concert_steering_module_frame.stl" scale="0.001 0.001 0.001"/>
      </geometry>
    </collision>
    <inertial>
      <origin rpy="0 0 0" xyz="0.090718433 0.0 -0.22670598"/>
      <mass value="7.6995028"/>
      <inertia ixx="0.44048889" ixy="-0.03668535" ixz="0.025595962" iyy="0.52073797" iyz="-0.0026667139" izz="0.69985532"/>
    </inertial>
  </link>
  <joint name="fixed_J_wheel_C" type="fixed">
    <axis rpy="0 0 0" xyz="0 0 1"/>
    <parent link="L_1_C"/>
    <child link="J_wheel_C_stator"/>
    <origin rpy="-3.141592653589793 1.5707963267948966 0.0" xyz="0.0 0.0 0.37015"/>
  </joint>
  <link name="J_wheel_C_stator">
    <inertial>
      <mass value="0.001"/>
      <inertia ixx="1.0e-06" ixy="0.0" ixz="0.0" iyy="1.0e-06" iyz="0.0" izz="1.0e-06"/>
    </inertial>
  </link>
  <joint name="J_wheel_C" type="revolute">
    <axis rpy="0 0 0" xyz="0 0 1"/>
    <parent link="J_wheel_C_stator"/>
    <child link="wheel_C"/>
    <origin rpy="0.0 -0.0 0.0" xyz="0.0 0.0 0.0"/>
    <limit effort="24.0" lower="-10000000000.0" upper="10000000000.0" velocity="9.5"/>
  </joint>
  <link name="wheel_C">
    <visual>
      <origin rpy="0.0 -0.0 0.0" xyz="0 0 0"/>
      <geometry>
        <mesh filename="package://concert_resources/models/modular/meshes/concert/concert_wheel.stl" scale="0.001 0.001 0.001"/>
      </geometry>
      <material name="black"/>
    </visual>
    <collision>
      <origin rpy="0.0 -0.0 0.0" xyz="0 0 0"/>
      <geometry>
        <cylinder length="0.1" radius="0.16"/>
      </geometry>
    </collision>
    <inertial>
      <origin rpy="0 0 0" xyz="0.0 0.0 -0.005"/>
      <mass value="4.0116207"/>
      <inertia ixx="0.028580559" ixy="0.0" ixz="0.0" iyy="0.028580559" iyz="0.0" izz="0.044954065"/>
    </inertial>
  </link>
  <joint name="fixed_J1_D" type="fixed">
    <axis rpy="0 0 0" xyz="0 0 1"/>
    <parent link="mobile_base"/>
    <child link="J1_D_stator"/>
    <origin rpy="-0.0 -1.5707963267948966 0.0" xyz="-0.37925 -0.3125 -0.195"/>
  </joint>
  <link name="J1_D_stator">
    <visual>
      <origin rpy="0.0 -0.0 0.0" xyz="0 0 0"/>
      <geometry>
        <mesh filename="package://concert_resources/models/modular/meshes/concert/concert_steering_connection_module.stl" scale="0.001 0.001 0.001"/>
      </geometry>
      <material name="blue"/>
    </visual>
    <collision>
      <origin rpy="0.0 -0.0 0.0" xyz="0 0 0"/>
      <geometry>
        <mesh filename="package://concert_resources/models/modular/meshes/concert/simple/concert_steering_connection_module.stl" scale="0.001 0.001 0.001"/>
      </geometry>
    </collision>
    <inertial>
      <origin rpy="0 0 0" xyz="-0.0079406061 0.0 0.037039629"/>
      <mass value="1.1813661"/>
      <inertia ixx="0.0026106263" ixy="0.0" ixz="0.00017928188" iyy="0.0027438806" iyz="0.0" izz="0.0025223123"/>
    </inertial>
  </link>
  <joint name="J1_D" type="revolute">
    <axis rpy="0 0 0" xyz="0 0 1"/>
    <parent link="J1_D_stator"/>
    <child link="L_1_D"/>
    <origin rpy="-1.5707963267948966 -0.0 1.5707963267948966" xyz="-0.022 0.0 0.06075"/>
    <limit effort="127.0" lower="-2.6" upper="2.6" velocity="8.1"/>
  </joint>
  <link name="L_1_D">
    <visual>
      <origin rpy="3.141592653589793 -0.0 0.0" xyz="0 0 0"/>
      <geometry>
        <mesh filename="package://concert_resources/models/modular/meshes/concert/concert_steering_module_frame.stl" scale="0.001 0.001 0.001"/>
      </geometry>
      <material name="blue"/>
    </visual>
    <collision>
      <origin rpy="3.141592653589793 -0.0 0.0" xyz="0 0 0"/>
      <geometry>
        <mesh filename="package://concert_resources/models/modular/meshes/concert/simple/concert_steering_module_frame.stl" scale="0.001 0.001 0.001"/>
      </geometry>
    </collision>
    <inertial>
      <origin rpy="0 0 0" xyz="0.090718433 0.0 -0.22670598"/>
      <mass value="7.6995028"/>
      <inertia ixx="0.44048889" ixy="-0.03668535" ixz="0.025595962" iyy="0.52073797" iyz="-0.0026667139" izz="0.69985532"/>
    </inertial>
  </link>
  <joint name="fixed_J_wheel_D" type="fixed">
    <axis rpy="0 0 0" xyz="0 0 1"/>
    <parent link="L_1_D"/>
    <child link="J_wheel_D_stator"/>
    <origin rpy="-3.141592653589793 1.5707963267948966 0.0" xyz="0.0 0.0 0.37015"/>
  </joint>
  <link name="J_wheel_D_stator">
    <inertial>
      <mass value="0.001"/>
      <inertia ixx="1.0e-06" ixy="0.0" ixz="0.0" iyy="1.0e-06" iyz="0.0" izz="1.0e-06"/>
    </inertial>
  </link>
  <joint name="J_wheel_D" type="revolute">
    <axis rpy="0 0 0" xyz="0 0 1"/>
    <parent link="J_wheel_D_stator"/>
    <child link="wheel_D"/>
    <origin rpy="0.0 -0.0 0.0" xyz="0.0 0.0 0.0"/>
    <limit effort="24.0" lower="-10000000000.0" upper="10000000000.0" velocity="9.5"/>
  </joint>
  <link name="wheel_D">
    <visual>
      <origin rpy="0.0 -0.0 0.0" xyz="0 0 0"/>
      <geometry>
        <mesh filename="package://concert_resources/models/modular/meshes/concert/concert_wheel.stl" scale="0.001 0.001 0.001"/>
      </geometry>
      <material name="black"/>
    </visual>
    <collision>
      <origin rpy="0.0 -0.0 0.0" xyz="0 0 0"/>
      <geometry>
        <cylinder length="0.1" radius="0.16"/>
      </geometry>
    </collision>
    <inertial>
      <origin rpy="0 0 0" xyz="0.0 0.0 -0.005"/>
      <mass value="4.0116207"/>
      <inertia ixx="0.028580559" ixy="0.0" ixz="0.0" iyy="0.028580559" iyz="0.0" izz="0.044954065"/>
    </inertial>
  </link>
</robot>
